#VRML_SIM R2019a utf8
WorldInfo {
}
Viewpoint {
  orientation -0.9959969247692124 -0.08745714223886124 -0.01847631244819914 0.636901980154465
  position 0.24222165978451227 2.324594858462804 1.6402221717223542
}
TexturedBackground {
}
TexturedBackgroundLight {
}
Floor {
}
Solid {
  translation 0 0.5 0
  children [
    Shape {
      appearance PBRAppearance {
        baseColor 0 0 0
      }
      geometry DEF G_BLACK_CYLINDER Cylinder {
        height 1
        radius 0.15
      }
    }
    HingeJoint {
      jointParameters HingeJointParameters {
        axis 0 1 0
        anchor 0 1 0
      }
      endPoint Solid {
        translation 0.19999883457801984 0.5049901115332591 0
        rotation 0 0 -1 2.3543834686280656e-06
        children [
          Shape {
            appearance PBRAppearance {
              baseColor 0.9372549019607843 0.1607843137254902 0.1607843137254902
            }
            geometry DEF G_RED_BOX Box {
              size 0.5 0.01 0.1
            }
          }
          HingeJoint {
            jointParameters HingeJointParameters {
              anchor 0.25 0 0
              staticFriction 0.01
            }
            endPoint Solid {
              translation 0.3 0 0
              rotation 1 0 0 0
              children [
                Shape {
                  appearance PBRAppearance {
                    baseColor 0.5411764705882353 0.8862745098039215 0.20392156862745098
                  }
                  geometry DEF G_GREEN_BOX Box {
                    size 0.1 0.01 0.1
                  }
                }
              ]
              boundingObject USE G_GREEN_BOX
              physics Physics {
              }
            }
          }
        ]
        boundingObject USE G_RED_BOX
        physics Physics {
        }
      }
    }
  ]
  boundingObject USE G_BLACK_CYLINDER
}
